package com.company.Part1.TryCatchFinally;

/**
 * Created by Iryna Furmaniuk on 11.07.2021.
 */
class App1 {
    public static void main(String[] args) {
        try {
            System.err.print(" 0");
            if (true) {throw new Error();}
            System.err.print(" 1");
        } catch(Error e) {
            System.err.print(" 2");
        } finally {
            System.err.print(" 3");
        }
        System.err.print(" 4");
    }
}
//>> 0 2 3 4

class App2 {
    public static void main(String[] args) {
        try {
            System.err.print(" 0");
            if (true) {throw new RuntimeException();}
            System.err.print(" 1");
        } catch(Error e) {
            System.err.print(" 2");
        } finally {
            System.err.print(" 3");
        }
        System.err.print(" 4");
    }
}
//>> 0 3
//        >> RUNTIME ERROR: Exception in thread "main" java.lang.RuntimeException

class App3 {
    public static void main(String[] args) {
        try {
            System.err.print(" 0");
            try {
                System.err.print(" 1");
                if (true) {throw new RuntimeException();}
                System.err.print(" 2");
            } catch (RuntimeException e) {
                System.err.print(" 3"); // ЗАХОДИМ - есть исключение
            } finally {
                System.err.print(" 4"); // заходим всегда
            }
            System.err.print(" 5");     // заходим - выполнение УЖЕ в норме
        } catch (Exception e) {
            System.err.print(" 6");     // не заходим - нет исключения, УЖЕ перехвачено
        } finally {
            System.err.print(" 7");     // заходим всегда
        }
        System.err.print(" 8");         // заходим - выполнение УЖЕ в норме
    }
}
//>> 0 1 3 4 5 7 8

class App4 {
    public static void main(String[] args) {
        try {
            System.err.print(" 0");
            try {
                System.err.print(" 1");
                if (true) {throw new Exception();}
                System.err.print(" 2");
            } catch (RuntimeException e) {
                System.err.print(" 3"); // НЕ заходим - есть исключение, но НЕПОДХОДЯЩЕГО ТИПА
            } finally {
                System.err.print(" 4"); // заходим всегда
            }
            System.err.print(" 5");     // не заходим - выполнение НЕ в норме
        } catch (Exception e) {
            System.err.print(" 6");     // ЗАХОДИМ - есть подходящее исключение
        } finally {
            System.err.print(" 7");     // заходим всегда
        }
        System.err.print(" 8");         // заходим - выполнение УЖЕ в норме
    }
}
//>> 0 1 4 6 7 8

class App5 {
    public static void main(String[] args) {
        try {
            System.err.print(" 0");
            try {
                System.err.print(" 1");
                if (true) {throw new Error();}
                System.err.print(" 2");
            } catch (RuntimeException e) {
                System.err.print(" 3"); // НЕ заходим - есть исключение, но НЕПОДХОДЯЩЕГО ТИПА
            } finally {
                System.err.print(" 4"); // заходим всегда
            }
            System.err.print(" 5");     // НЕ заходим - выполнение НЕ в норме
        } catch (Exception e) {
            System.err.print(" 6");     // не заходим - есть исключение, но НЕПОДХОДЯЩЕГО ТИПА
        } finally {
            System.err.print(" 7");     // заходим всегда
        }
        System.err.print(" 8");         // не заходим - выполнение НЕ в норме
    }
}
//>> 0 1 4 7
//        >> RUNTIME EXCEPTION: Exception in thread "main" java.lang.Error


















